<?xml version="1.0" ?>
<!-- =================================================================================== -->
<!-- |    This document was autogenerated by xacro from metafly.urdf.xacro             | -->
<!-- |    EDITING THIS FILE BY HAND IS NOT RECOMMENDED                                 | -->
<!-- =================================================================================== -->
<robot name="metafly">
  <material name="black">
    <color rgba="0.0 0.0 0.0 1.0"/>
  </material>
  <material name="blue">
    <color rgba="0.0 0.0 0.8 1.0"/>
  </material>
  <material name="green">
    <color rgba="0.0 1.0 0.0 1.0"/>
  </material>
  <material name="dark_grey">
    <color rgba="0.2 0.2 0.2 1.0"/>
  </material>
  <material name="grey">
    <color rgba="0.5 0.5 0.5 1.0"/>
  </material>
  <material name="light_grey">
    <color rgba="0.8 0.8 0.8 1.0"/>
  </material>
  <material name="brown">
    <color rgba="0.54 0.27 0.07 1.0"/>
  </material>
  <material name="red">
    <color rgba="0.8 0.0 0.0 1.0"/>
  </material>
  <material name="white">
    <color rgba="1.0 1.0 1.0 1.0"/>
  </material>
  <!-- LINKS -->
  <!-- base link -->
  <link name="base_link">
    <!-- body -->
    <visual>
      <origin rpy="1.5707963267948966 0 0" xyz="0 0 0"/>
      <geometry>
        <cylinder length="0.25" radius="0.025"/>
      </geometry>
      <material name="light_grey"/>
    </visual>
    <!-- head -->
    <visual>
      <origin rpy="0 0 0" xyz="0 0.125 0"/>
      <geometry>
        <sphere radius="0.037500000000000006"/>
      </geometry>
    </visual>
  </link>
  <!-- wing 1 -->
  <link name="wing1">
    <visual>
      <origin rpy="0 0 0" xyz="-0.125 0 0"/>
      <geometry>
        <box size="0.25 0.25 0.001"/>
      </geometry>
      <material name="red"/>
    </visual>
  </link>
  <!-- wing 2 -->
  <link name="wing2">
    <visual>
      <origin rpy="0 0 0" xyz="0.125 0 0"/>
      <geometry>
        <box size="0.25 0.25 0.001"/>
      </geometry>
      <material name="green"/>
    </visual>
  </link>
  <!-- JOINTS -->
  <!-- joint 1 -->
  <joint name="joint1" type="revolute">
    <origin rpy="0 0 0" xyz="0 0 0"/>
    <parent link="base_link"/>
    <child link="wing1"/>
    <axis xyz="0 1 0"/>
    <limit effort="0" lower="-1.5707963267948966" upper="1.5707963267948966" velocity="0"/>
  </joint>
  <!-- joint 2 -->
  <joint name="joint2" type="revolute">
    <origin rpy="0 0 0" xyz="0 0 0"/>
    <parent link="base_link"/>
    <child link="wing2"/>
    <axis xyz="0 1 0"/>
    <limit effort="0" lower="-1.5707963267948966" upper="1.5707963267948966" velocity="0"/>
  </joint>
  <!-- END JOINTS -->
</robot>
